2021-07-21 08:45:08,942 — DfHelper — ERROR — file not found
Traceback (most recent call last):
  File "/Users/ea/Projects/a-b-testing/scripts/df_helper.py", line 25, in read_csv
    df = pd.read_csv(csv_path, na_values=missing_values)
  File "/usr/local/lib/python3.9/site-packages/pandas/io/parsers.py", line 610, in read_csv
    return _read(filepath_or_buffer, kwds)
  File "/usr/local/lib/python3.9/site-packages/pandas/io/parsers.py", line 462, in _read
    parser = TextFileReader(filepath_or_buffer, **kwds)
  File "/usr/local/lib/python3.9/site-packages/pandas/io/parsers.py", line 819, in __init__
    self._engine = self._make_engine(self.engine)
  File "/usr/local/lib/python3.9/site-packages/pandas/io/parsers.py", line 1050, in _make_engine
    return mapping[engine](self.f, **self.options)  # type: ignore[call-arg]
  File "/usr/local/lib/python3.9/site-packages/pandas/io/parsers.py", line 1867, in __init__
    self._open_handles(src, kwds)
  File "/usr/local/lib/python3.9/site-packages/pandas/io/parsers.py", line 1362, in _open_handles
    self.handles = get_handle(
  File "/usr/local/lib/python3.9/site-packages/pandas/io/common.py", line 642, in get_handle
    handle = open(
FileNotFoundError: [Errno 2] No such file or directory: 'test.csv'
2021-07-21 08:45:08,956 — DfHelper — INFO — file saved as csv
2021-07-21 08:46:15,720 — DfHelper — DEBUG — file read as csv
2021-07-21 08:46:15,724 — DfHelper — INFO — file saved as csv
